<!DOCTYPE html>
<html lang="en">
<head>
    <meta charset="UTF-8">
    <meta name="viewport" content="width=device-width, initial-scale=1.0">
    <title>Error Handling</title>
</head>
<body>
    <p>Please see the F12 console</p>
    <script>
        const timeoutIntervalInMs = 500;
        const logToConsole = (text, caller) => console.log(text, caller);
        const handleError = (error, caller) => console.log(error, caller);
        
        // callback hell
        const getAndProcessOriginal = function(caller) {
            try {
                // get data
                const rawData = new Date();
                // throw new Error("simulated network error");
                setTimeout(function() {
                    try {
                        // process data
                        const processedData = rawData.toTimeString();
                        // throw new Error("simulated network error");
                        setTimeout(function() {
                            // display data
                            logToConsole(processedData, caller);
                        }, timeoutIntervalInMs);
                    } catch(e) {
                        handleError(e, caller);
                    }
                }, timeoutIntervalInMs);
            } catch(e) {
                handleError(e, caller);
            }
        };
        getAndProcessOriginal("from getAndProcessOriginal");
        
        // arrow functions
        const getAndProcessUsingCallbacks = (caller) => {
            const getData = (callback) => {
                try {
                    // throw new Error("simulated network error");
                    const rawData = new Date();
                    setTimeout(() => callback(rawData), timeoutIntervalInMs);
                } catch(e) {
                    handleError(e, caller);
                }
            };
            const processData = (rawData, callback) => {
                try {
                    // throw new Error("simulated network error");
                    const processedData = rawData.toTimeString();
                    setTimeout(() => callback(processedData), timeoutIntervalInMs);
                } catch(e) {
                    handleError(e, caller);
                }
            };

            // wrapping getData with try/catch won't handle exceptions in processData or logToConsole
            const processDataCallback = (processedData) => logToConsole(processedData, caller);
            const getDataCallback = (rawData) => processData(rawData, processDataCallback);
            getData(getDataCallback);
        };
        getAndProcessUsingCallbacks("from getAndProcessUsingCallbacks");

        // promises
        const getAndProcessUsingPromises = (caller) => {
            const getData = () => {
                try {
                    // throw new Error("simulated network error");
                    const rawData = new Date();
                    const executor = (resolve) => setTimeout(() => resolve(rawData), timeoutIntervalInMs);
                    return new Promise(executor);
                } catch(e) {
                    return Promise.reject(e);
                }
            };
            const processData = (rawData) => {
                try {
                    // throw new Error("simulated network error");
                    const processedData = rawData.toTimeString();
                    const executor = (resolve) => setTimeout(() => resolve(processedData), timeoutIntervalInMs)
                    return new Promise(executor);
                } catch(e) {
                    return Promise.reject(e);
                }
            };

            const getDataPromise = getData();
            const processDataPromise = getDataPromise.then(rawData => processData(rawData));
            const logToConsolePromise = processDataPromise.then(processedData => logToConsole(processedData, caller));
            logToConsolePromise.catch(e => handleError(e, caller));
        };
        getAndProcessUsingPromises("from getAndProcessUsingPromises");

        // async/await
        const getAndProcessUsingAsync = async (caller) => {
            const getDataAsync = async () => {
                // throw new Error("simulated network error");
                const rawData = new Date();
                const executor = (resolve) => setTimeout(() => resolve(rawData), timeoutIntervalInMs);
                return new Promise(executor);
            };

            const processDataAsync = async (rawData) => {
                // throw new Error("simulated network error");
                const processedData = rawData.toTimeString();
                const executor = (resolve) => setTimeout(() => resolve(processedData), timeoutIntervalInMs)
                return new Promise(executor);
            };

            try {
                // throw new Error("simulated network error");
                const rawData = await getDataAsync();
                const processedData = await processDataAsync(rawData);
                logToConsole(processedData, caller);
            } catch(e) {
                handleError(e, caller);
            }
        }
        getAndProcessUsingAsync("from getAndProcessUsingAsync");
    </script>
</body>
</html>